Workbook

Sheet input
A1: Date | B1: Month | C1: Category | D1: Description | E1: Amount | I1: Catogories
A2: 44562 | B2: =TEXT(A2,"MMMM") -> January | C2: Rent | D2: Apartment split with friend | E2: 1250 | I2: Rent
A3: 44562 | B3: =TEXT(A3,"MMMM") -> January | C3: Utilities | D3: Higher month than usual | E3: 140 | I3: Utilities
A4: 44562 | B4: =TEXT(A4,"MMMM") -> January | C4: Transport | D4: Metro card | E4: 52 | I4: Transport
A5: 44569 | B5: =TEXT(A5,"MMMM") -> January | C5: Groceries | D5: Walmart shopping | E5: 449 | I5: Groceries
A6: 44572 | B6: =TEXT(A6,"MMMM") -> January | C6: Leisure | D6: Hotel in NYC | E6: 245 | I6: Leisure
A7: 44573 | B7: =TEXT(A7,"MMMM") -> January | C7: Leisure | D7: Dinner with friends (invited my partner) | E7: 168 | I7: Bonus
A8: 44573 | B8: =TEXT(A8,"MMMM") -> January | C8: Leisure | D8: Drake concert | E8: 149 | I8: Side Hustle
A9: 44575 | B9: =TEXT(A9,"MMMM") -> January | C9: Other | D9: Bought new clothes | E9: 249 | I9: Base Salary
A10: 44592 | B10: =TEXT(A10,"MMMM") -> January | C10: Bonus | D10: Commissions from each sale | E10: 850 | I10: Investments
A11: 44592 | B11: =TEXT(A11,"MMMM") -> January | C11: Base Salary | D11: 9-5 job | E11: 20000 | I11: Other
A12: 44592 | B12: =TEXT(A12,"MMMM") -> January | C12: Side Hustle | D12: Startup idea $ | E12: 500
A13: 44593 | B13: =TEXT(A13,"MMMM") -> February | C13: Rent | D13: Apartment split with friend | E13: 1250
A14: 44593 | B14: =TEXT(A14,"MMMM") -> February | C14: Utilities | D14: Average month | E14: 105
A15: 44593 | B15: =TEXT(A15,"MMMM") -> February | C15: Transport | D15: Metro card | E15: 200
A16: 44600 | B16: =TEXT(A16,"MMMM") -> February | C16: Groceries | D16: Walmart shopping | E16: 305
A17: 44603 | B17: =TEXT(A17,"MMMM") -> February | C17: Leisure | D17: Drinks out | E17: 28
A18: 44604 | B18: =TEXT(A18,"MMMM") -> February | C18: Leisure | D18: Date night | E18: 99
A19: 44604 | B19: =TEXT(A19,"MMMM") -> February | C19: Leisure | D19: Tennis x2 | E19: 67
A20: 44606 | B20: =TEXT(A20,"MMMM") -> February | C20: Other | D20: Snacks | E20: 18
A21: 44620 | B21: =TEXT(A21,"MMMM") -> February | C21: Bonus | D21: Commissions from each sale | E21: 1025
A22: 44620 | B22: =TEXT(A22,"MMMM") -> February | C22: Base Salary | D22: 9-5 job | E22: 20000
A23: 44620 | B23: =TEXT(A23,"MMMM") -> February | C23: Side Hustle | D23: Startup idea $ | E23: 600
... A54: 44693 | B54: =TEXT(A54,"MMMM") -> May | C54: Leisure | D54: Dinner with friends (invited my partner) | E54: 168
A55: 44693 | B55: =TEXT(A52,"MMMM") -> May | C55: Leisure | D55: NBA game | E55: 233
A56: 44695 | B56: =TEXT(A56,"MMMM") -> May | C56: Other | D56: Bought new clothes | E56: 249
A57: 44709 | B57: =TEXT(A57,"MMMM") -> May | C57: Bonus | D57: Commissions from each sale | E57: 1450
A58: 44709 | B58: =TEXT(A58,"MMMM") -> May | C58: Base Salary | D58: 9-5 job | E58: 20000
A59: 44709 | B59: =TEXT(A59,"MMMM") -> May | C59: Side Hustle | D59: Startup idea $ | E59: 366
A60: 44710 | B60: =TEXT(A60,"MMMM") -> May | C60: Side Hustle | D60: Lemonade | E60: 1000
A61: 44713 | B61: =TEXT(A61,"MMMM") -> June | C61: Rent | D61: Apartment split with friend | E61: 1250
A62: 44713 | B62: =TEXT(A62,"MMMM") -> June | C62: Utilities | D62: Higher month than usual | E62: 152
A63: 44713 | B63: =TEXT(A63,"MMMM") -> June | C63: Transport | D63: Metro card | E63: 52
A64: 44720 | B64: =TEXT(A64,"MMMM") -> June | C64: Groceries | D64: Walmart shopping | E64: 560
A65: 44723 | B65: =TEXT(A65,"MMMM") -> June | C65: Leisure | D65: Hotel in Dallas | E65: 280
A66: 44724 | B66: =TEXT(A66,"MMMM") -> June | C66: Leisure | D66: Dinner with friends (invited my partner) | E66: 250
A67: 44724 | B67: =TEXT(A67,"MMMM") -> June | C67: Leisure | D67: Music concert | E67: 99
... A70: 44742 | B70: =TEXT(A70,"MMMM") -> June | C70: Side Hustle | D70: Startup idea $ | E70: 199
A71: 45823 | B71: June | C71: Other | D71: restaurant | E71: 500
A72: 44742 | B72: =TEXT(A72,"MMMM") -> June | C72: Investments | D72: Post Office | E72: 1000
...

Sheet Dashboard
B1: Finance Tracker
B6: Figures in USD | C6: January | D6: February | E6: March | F6: April | G6: May | H6: June | I6: July | J6: August | K6: September | L6: October | M6: November | N6: December | O6: Column1 | P6: YTD Total
B7: Income:
B8: Base Salary | C8: =SUMIFS(input!E:E, input!B:B,Dashboard!C6, input!C:C, Dashboard!B8) -> 20000 | D8: =SUMIFS(input!$E:$E, input!$B:$B, Dashboard!C6, input!$C:$C, Dashboard!B8) -> 20000 | E8: =SUMIFS(input!$E:$E, input!$B:$B, Dashboard!E6, input!$C:$C, Dashboard!B8) -> 20000 | F8: =SUMIFS(input!$E:$E, input!$B:$B, Dashboard!F6, input!$C:$C, Dashboard!B8) -> 20000 | G8: =SUMIFS(input!$E:$E, input!$B:$B, Dashboard!G6, input!$C:$C, Dashboard!B8) -> 20000 | H8: =SUMIFS(input!$E:$E, input!$B:$B, Dashboard!H6, input!$C:$C, Dashboard!$B8) -> 20000 | I8: =SUMIFS(input!$E:$E, input!$B:$B, Dashboard!I6, input!$C:$C, Dashboard!$B8) -> 20000 | J8: =SUMIFS(input!$E:$E, input!$B:$B, Dashboard!J6, input!$C:$C, Dashboard!$B8) -> 20000 | K8: =SUMIFS(input!$E:$E, input!$B:$B, Dashboard!K6, input!$C:$C, Dashboard!$B8) -> 20000 | L8: =SUMIFS(input!$E:$E, input!$B:$B, Dashboard!L6, input!$C:$C, Dashboard!$B8) -> 20000 | M8: =SUMIFS(input!$E:$E, input!$B:$B, Dashboard!M6, input!$C:$C, Dashboard!$B8) -> 0 | N8: =SUMIFS(input!$E:$E, input!$B:$B, Dashboard!N6, input!$C:$C, Dashboard!$B8) -> 0 | P8: =SUM(C8:N8) -> 200000
B9: Bonus | C9: =SUMIFS(input!E:E, input!B:B, Dashboard!C6, input!C:C, Dashboard!$B9) -> 850 | D9: =SUMIFS(input!$E:$E,input!$B:$B,Dashboard!D6,input!$C:$C,Dashboard!$B9) -> 1025 | E9: =SUMIFS(input!$E:$E,input!$B:$B,Dashboard!E6,input!$C:$C,Dashboard!$B9) -> 999 | F9: =SUMIFS(input!$E:$E,input!$B:$B,Dashboard!F6,input!$C:$C,Dashboard!$B9) -> 1243 | G9: =SUMIFS(input!$E:$E,input!$B:$B,Dashboard!G6,input!$C:$C,Dashboard!$B9) -> 1450 | H9: =SUMIFS(input!$E:$E,input!$B:$B,Dashboard!H6,input!$C:$C,Dashboard!$B9) -> 2232 | I9: =SUMIFS(input!$E:$E,input!$B:$B,Dashboard!I6,input!$C:$C,Dashboard!$B9) -> 2231 | J9: =SUMIFS(input!$E:$E,input!$B:$B,Dashboard!J6,input!$C:$C,Dashboard!$B9) -> 2300 | K9: =SUMIFS(input!$E:$E,input!$B:$B,Dashboard!K6,input!$C:$C,Dashboard!$B9) -> 2300 | ... N9: =SUMIFS(input!$E:$E,input!$B:$B,Dashboard!N6,input!$C:$C,Dashboard!$B9) -> 0 | P9: =SUM(C9:N9) -> 17430
B10: Side Hustle | C10: =SUMIFS(input!$E:$E, input!$B:$B, Dashboard!C6, input!$C:$C, Dashboard!B10) -> 500 | D10: =SUMIFS(input!$E:$E, input!$B:$B, Dashboard!D6, input!$C:$C, Dashboard!$B10) -> 600 | E10: =SUMIFS(input!$E:$E, input!$B:$B, Dashboard!E6, input!$C:$C, Dashboard!$B10) -> 1000 | F10: =SUMIFS(input!$E:$E, input!$B:$B, Dashboard!F6, input!$C:$C, Dashboard!$B10) -> 1500 | G10: =SUMIFS(input!$E:$E, input!$B:$B, Dashboard!G6, input!$C:$C, Dashboard!$B10) -> 1366 | H10: =SUMIFS(input!$E:$E, input!$B:$B, Dashboard!H6, input!$C:$C, Dashboard!$B10) -> 199 | I10: =SUMIFS(input!$E:$E, input!$B:$B, Dashboard!I6, input!$C:$C, Dashboard!$B10) -> 1500 | J10: =SUMIFS(input!$E:$E, input!$B:$B, Dashboard!J6, input!$C:$C, Dashboard!$B10) -> 570 | K10: =SUMIFS(input!$E:$E, input!$B:$B, Dashboard!K6, input!$C:$C, Dashboard!$B10) -> 780 | ... N10: =SUMIFS(input!$E:$E, input!$B:$B, Dashboard!N6, input!$C:$C, Dashboard!$B10) -> 0 | P10: =SUM(C10:N10) -> 10015
B11: Investments | C11: =SUMIFS(input!$E:$E, input!$B:$B, Dashboard!C6, input!$C:$C, Dashboard!$B11) -> 1000 | D11: =SUMIFS(input!$E:$E, input!$B:$B, Dashboard!D6, input!$C:$C, Dashboard!$B11) -> 1000 | E11: =SUMIFS(input!$E:$E, input!$B:$B, Dashboard!E6, input!$C:$C, Dashboard!$B11) -> 299 | F11: =SUMIFS(input!$E:$E, input!$B:$B, Dashboard!F6, input!$C:$C, Dashboard!$B11) -> 359 | G11: =SUMIFS(input!$E:$E, input!$B:$B, Dashboard!G6, input!$C:$C, Dashboard!$B11) -> 15000 | H11: =SUMIFS(input!$E:$E, input!$B:$B, Dashboard!H6, input!$C:$C, Dashboard!$B11) -> 1000 | I11: =SUMIFS(input!$E:$E, input!$B:$B, Dashboard!I6, input!$C:$C, Dashboard!$B11) -> 215 | J11: =SUMIFS(input!$E:$E, input!$B:$B, Dashboard!J6, input!$C:$C, Dashboard!$B11) -> 350 | ... N11: =SUMIFS(input!$E:$E, input!$B:$B, Dashboard!N6, input!$C:$C, Dashboard!$B11) -> 0 | P11: =SUM(C11:N11) -> 20598
B12: Total Income | C12: =SUM(C8:C11) -> 22350 | D12: =SUM(D8:D11) -> 22625 | E12: =SUM(E8:E11) -> 22298 | F12: =SUM(F8:F11) -> 23102 | G12: =SUM(G8:G11) -> 37816 | H12: =SUM(H8:H11) -> 23431 | I12: =SUM(I8:I11) -> 23946 | J12: =SUM(J8:J11) -> 23220 | ... N12: =SUM(N8:N11) -> 0 | P12: =SUM(C12:N12) -> 248043
B13: MoM % growth | C13: =IF(C12=0, "", D12/C12 - 1) -> 0.012304251 | D13: =IF(C12=0, "", D12/C12 - 1) -> 0.012304251 | E13: =IF(D12=0, "", E12/D12 - 1) -> -0.014453039 | F13: =IF(E12=0, "", F12/E12 - 1) -> 0.036057045 | G13: =IF(F12=0, "", G12/F12 - 1) -> 0.63691455 | H13: =IF(G12=0, "", H12/G12 - 1) -> -0.38039454 | I13: =IF(H12=0, "", I12/H12 - 1) -> 0.021979429 | J13: =IF(I12=0, "", J12/I12 - 1) -> -0.030318216 | K13: =IF(J12=0, "", K12/J12 - 1) -> 0.037037037 | ... N13: =IF(M12=0, "", N12/M12 - 1)
B15: Expenses:
B16: Rent | C16: =SUMIFS(input!E:E, input!B:B,Dashboard!C6, input!C:C, Dashboard!B16) -> 1250 | D16: =SUMIFS(input!$E:$E, input!$B:$B, Dashboard!D6, input!$C:$C, Dashboard!B16) -> 1250 | E16: =SUMIFS(input!$E:$E, input!$B:$B, Dashboard!E6, input!$C:$C, Dashboard!$B16) -> 1250 | F16: =SUMIFS(input!$E:$E, input!$B:$B, Dashboard!F6, input!$C:$C, Dashboard!$B16) -> 1250 | G16: =SUMIFS(input!$E:$E, input!$B:$B, Dashboard!G6, input!$C:$C, Dashboard!$B16) -> 1250 | H16: =SUMIFS(input!$E:$E, input!$B:$B, Dashboard!H6, input!$C:$C, Dashboard!$B16) -> 1250 | I16: =SUMIFS(input!$E:$E, input!$B:$B, Dashboard!I6, input!$C:$C, Dashboard!$B16) -> 1250 | J16: =SUMIFS(input!$E:$E, input!$B:$B, Dashboard!J6, input!$C:$C, Dashboard!$B16) -> 1250 | K16: =SUMIFS(input!$E:$E, input!$B:$B, Dashboard!K6, input!$C:$C, Dashboard!$B16) -> 1250 | L16: =SUMIFS(input!$E:$E,input!$B:$B,Dashboard!L6,input!$C:$C,Dashboard!$B16) -> 1250 | M16: =SUMIFS(input!$E:$E, input!$B:$B, Dashboard!M6, input!$C:$C, Dashboard!$B16) -> 0 | N16: =SUMIFS(input!$E:$E, input!$B:$B, Dashboard!N6, input!$C:$C, Dashboard!$B16) -> 0 | P16: =SUM(C16:N16) -> 12500
B17: Utilities | C17: =SUMIFS(input!$E:$E, input!$B:$B, Dashboard!C6, input!$C:$C, Dashboard!$B17) -> 140 | D17: =SUMIFS(input!$E:$E, input!$B:$B, Dashboard!D6, input!$C:$C, Dashboard!$B17) -> 105 | E17: =SUMIFS(input!$E:$E, input!$B:$B, Dashboard!E6, input!$C:$C, Dashboard!$B17) -> 110 | F17: =SUMIFS(input!$E:$E, input!$B:$B, Dashboard!F6, input!$C:$C, Dashboard!$B17) -> 140 | G17: =SUMIFS(input!$E:$E, input!$B:$B, Dashboard!G6, input!$C:$C, Dashboard!$B17) -> 152 | H17: =SUMIFS(input!$E:$E, input!$B:$B, Dashboard!H6, input!$C:$C, Dashboard!$B17) -> 152 | I17: =SUMIFS(input!$E:$E, input!$B:$B, Dashboard!I6, input!$C:$C, Dashboard!$B17) -> 110 | J17: =SUMIFS(input!$E:$E, input!$B:$B, Dashboard!J6, input!$C:$C, Dashboard!$B17) -> 110 | ... N17: =SUMIFS(input!$E:$E, input!$B:$B, Dashboard!N6, input!$C:$C, Dashboard!$B17) -> 0 | P17: =SUM(C17:N17) -> 1471
B18: Transport | C18: =SUMIFS(input!$E:$E, input!$B:$B, Dashboard!C6, input!$C:$C, Dashboard!$B18) -> 52 | D18: =SUMIFS(input!$E:$E, input!$B:$B, Dashboard!D6, input!$C:$C, Dashboard!$B18) -> 200 | E18: =SUMIFS(input!$E:$E, input!$B:$B, Dashboard!E6, input!$C:$C, Dashboard!$B18) -> 120 | F18: =SUMIFS(input!$E:$E, input!$B:$B, Dashboard!F6, input!$C:$C, Dashboard!$B18) -> 190 | G18: =SUMIFS(input!$E:$E, input!$B:$B, Dashboard!G6, input!$C:$C, Dashboard!$B18) -> 150 | H18: =SUMIFS(input!$E:$E, input!$B:$B, Dashboard!H6, input!$C:$C, Dashboard!$B18) -> 52 | I18: =SUMIFS(input!$E:$E, input!$B:$B, Dashboard!I6, input!$C:$C, Dashboard!$B18) -> 123 | J18: =SUMIFS(input!$E:$E, input!$B:$B, Dashboard!J6, input!$C:$C, Dashboard!$B18) -> 99 | ... N18: =SUMIFS(input!$E:$E, input!$B:$B, Dashboard!N6, input!$C:$C, Dashboard!$B18) -> 0 | P18: =SUM(C18:N18) -> 1252
B19: Groceries | C19: =SUMIFS(input!$E:$E, input!$B:$B, Dashboard!C6, input!$C:$C, Dashboard!$B19) -> 449 | D19: =SUMIFS(input!$E:$E, input!$B:$B, Dashboard!D6, input!$C:$C, Dashboard!$B19) -> 305 | E19: =SUMIFS(input!$E:$E, input!$B:$B, Dashboard!E6, input!$C:$C, Dashboard!$B19) -> 208 | F19: =SUMIFS(input!$E:$E, input!$B:$B, Dashboard!F6, input!$C:$C, Dashboard!$B19) -> 449 | G19: =SUMIFS(input!$E:$E, input!$B:$B, Dashboard!G6, input!$C:$C, Dashboard!$B19) -> 449 | H19: =SUMIFS(input!$E:$E, input!$B:$B, Dashboard!H6, input!$C:$C, Dashboard!$B19) -> 560 | I19: =SUMIFS(input!$E:$E, input!$B:$B, Dashboard!I6, input!$C:$C, Dashboard!$B19) -> 208 | J19: =SUMIFS(input!$E:$E, input!$B:$B, Dashboard!J6, input!$C:$C, Dashboard!$B19) -> 208 | ... N19: =SUMIFS(input!$E:$E, input!$B:$B, Dashboard!N6, input!$C:$C, Dashboard!$B19) -> 0 | P19: =SUM(C19:N19) -> 3550
B20: Leisure | C20: =SUMIFS(input!$E:$E, input!$B:$B, Dashboard!C6, input!$C:$C, Dashboard!$B20) -> 562 | D20: =SUMIFS(input!$E:$E, input!$B:$B, Dashboard!D6, input!$C:$C, Dashboard!$B20) -> 194 | E20: =SUMIFS(input!$E:$E, input!$B:$B, Dashboard!E6, input!$C:$C, Dashboard!$B20) -> 405 | F20: =SUMIFS(input!$E:$E, input!$B:$B, Dashboard!F6, input!$C:$C, Dashboard!$B20) -> 713 | G20: =SUMIFS(input!$E:$E, input!$B:$B, Dashboard!G6, input!$C:$C, Dashboard!$B20) -> 646 | H20: =SUMIFS(input!$E:$E, input!$B:$B, Dashboard!H6, input!$C:$C, Dashboard!$B20) -> 629 | I20: =SUMIFS(input!$E:$E, input!$B:$B, Dashboard!I6, input!$C:$C, Dashboard!$B20) -> 275 | J20: =SUMIFS(input!$E:$E, input!$B:$B, Dashboard!J6, input!$C:$C, Dashboard!$B20) -> 147 | ... N20: =SUMIFS(input!$E:$E, input!$B:$B, Dashboard!N6, input!$C:$C, Dashboard!$B20) -> 0 | P20: =SUM(C20:N20) -> 3878
B21: Other | C21: =SUMIFS(input!$E:$E, input!$B:$B, Dashboard!C6, input!$C:$C, Dashboard!$B21) -> 249 | D21: =SUMIFS(input!$E:$E, input!$B:$B, Dashboard!D6, input!$C:$C, Dashboard!$B21) -> 18 | E21: =SUMIFS(input!$E:$E, input!$B:$B, Dashboard!E6, input!$C:$C, Dashboard!$B21) -> 199 | F21: =SUMIFS(input!$E:$E, input!$B:$B, Dashboard!F6, input!$C:$C, Dashboard!$B21) -> 249 | G21: =SUMIFS(input!$E:$E, input!$B:$B, Dashboard!G6, input!$C:$C, Dashboard!$B21) -> 249 | H21: =SUMIFS(input!$E:$E, input!$B:$B, Dashboard!H6, input!$C:$C, Dashboard!$B21) -> 500 | I21: =SUMIFS(input!$E:$E, input!$B:$B, Dashboard!I6, input!$C:$C, Dashboard!$B21) -> 399 | J21: =SUMIFS(input!$E:$E, input!$B:$B, Dashboard!J6, input!$C:$C, Dashboard!$B21) -> 149 | ... N21: =SUMIFS(input!$E:$E, input!$B:$B, Dashboard!N6, input!$C:$C, Dashboard!$B21) -> 0 | P21: =SUM(C21:N21) -> 2340
B22: Total Expenses | C22: =SUM(C16:C21) -> 2702 | D22: =SUM(D16:D21) -> 2072 | E22: =SUM(E16:E21) -> 2292 | F22: =SUM(F16:F21) -> 2991 | G22: =SUM(G16:G21) -> 2896 | H22: =SUM(H16:H21) -> 3143 | I22: =SUM(I16:I21) -> 2365 | J22: =SUM(J16:J21) -> 1963 | ... N22: =SUM(N16:N21) -> 0 | P22: =SUM(C22:N22) -> 24991
B23: MoM % growth | C23: 0 | D23: =D22/C22-1 -> -0.23316062 | E23: =E22/D22-1 -> 0.10617761 | F23: =F22/E22-1 -> 0.30497382 | G23: =G22/F22-1 -> -0.031761953 | H23: =H22/G22-1 -> 0.085290055 | I23: =I22/H22-1 -> -0.2475342 | J23: =J22/I22-1 -> -0.16997886 | K23: =K22/J22-1 -> 0.17473255 | L23: =L22/K22-1 -> -0.01951431 | M23: -1 | N23: =--D14 -> 0
B25: Savings | C25: =C12-C22 -> 19648 | D25: =D12-D22 -> 20553 | E25: =E12-E22 -> 20006 | F25: =F12-F22 -> 20111 | G25: =G12-G22 -> 34920 | H25: =H12-H22 -> 20288 | I25: =I12-I22 -> 21581 | J25: =J12-J22 -> 21257 | ... N25: =N12-N22 -> 0 | P25: =SUM(C25:N25) -> 223052
B26: MoM % growth | C26: =IF(C25=0, "", D25/C25 - 1) -> 0.046060668 | D26: =D25/C25-1 -> 0.046060668 | E26: =E25/D25-1 -> -0.02661412 | F26: =F25/E25-1 -> 0.0052484255 | G26: =G25/F25-1 -> 0.73636318 | H26: =H25/G25-1 -> -0.41901489 | I26: =I25/H25-1 -> 0.063732256 | J26: =J25/I25-1 -> -0.015013206 | K26: =K25/J25-1 -> 0.0243214 | L26: =L25/K25-1 -> 0.052356021 | M26: =IF(L25=0,"",M25/L25-1) -> -1 | N26: =IF(M25=0,"",N25/M25-1)
B28: Income Breakdown | J28: Expenses Breakdown
